<?xml version="1.0" encoding="utf-8"?>
<!-- This URDF was automatically created by SolidWorks to URDF Exporter! Originally created by Stephen Brawner (brawner@gmail.com) 
     Commit Version: 1.6.0-4-g7f85cfe  Build Version: 1.6.7995.38578
     For more information, please see http://wiki.ros.org/sw_urdf_exporter -->
<robot
  name="mega_robot_1st_urdf">
  <link
    name="base_link">
    <inertial>
      <origin
        xyz="-1.87624709687602E-05 4.00393253470889E-06 0.0833501296982546"
        rpy="0 0 0" />
      <mass
        value="3.32318803847545" />
      <inertia
        ixx="0.0126124113528869"
        ixy="2.56927373183442E-07"
        ixz="-3.71594539232469E-07"
        iyy="0.012835664676862"
        iyz="1.24835861123759E-06"
        izz="0.0128716305283176" />
    </inertial>
    <visual>
      <origin
        xyz="0 0 0"
        rpy="0 0 0" />
      <geometry>
        <mesh
          filename="package://mega_robot_1st_urdf/meshes/base_link.STL" />
      </geometry>
      <material
        name="">
        <color
          rgba="0.752941176470588 0.752941176470588 0.752941176470588 1" />
      </material>
    </visual>
    <collision>
      <origin
        xyz="0 0 0"
        rpy="0 0 0" />
      <geometry>
        <mesh
          filename="package://mega_robot_1st_urdf/meshes/base_link.STL" />
      </geometry>
    </collision>
  </link>
  <link
    name="trunk1">
    <inertial>
      <origin
        xyz="0.0491785569020739 -0.00235223999921011 0.17440079407548"
        rpy="0 0 0" />
      <mass
        value="7.27407224770367" />
      <inertia
        ixx="0.109814628636415"
        ixy="-3.71614116202833E-05"
        ixz="-0.0289062391193289"
        iyy="0.128784171279192"
        iyz="-8.18644513669917E-05"
        izz="0.0345729666831015" />
    </inertial>
    <visual>
      <origin
        xyz="0 0 0"
        rpy="0 0 0" />
      <geometry>
        <mesh
          filename="package://mega_robot_1st_urdf/meshes/trunk1.STL" />
      </geometry>
      <material
        name="">
        <color
          rgba="0.752941176470588 0.752941176470588 0.752941176470588 1" />
      </material>
    </visual>
    <collision>
      <origin
        xyz="0 0 0"
        rpy="0 0 0" />
      <geometry>
        <mesh
          filename="package://mega_robot_1st_urdf/meshes/trunk1.STL" />
      </geometry>
    </collision>
  </link>
  <joint
    name="trunk_J1"
    type="revolute">
    <origin
      xyz="0 0 0.161000000045019"
      rpy="0 0 3.14159265358979" />
    <parent
      link="base_link" />
    <child
      link="trunk1" />
    <axis
      xyz="0 0 1" />
    <limit
      lower="-3.1416"
      upper="3.1416"
      effort="0"
      velocity="2.0" />
  </joint>
  <link
    name="trunk2">
    <inertial>
      <origin
        xyz="-0.112228832521444 -0.104669015239314 -0.00184659131772547"
        rpy="0 0 0" />
      <mass
        value="8.8678292384067" />
      <inertia
        ixx="0.0501266523579521"
        ixy="-0.0256643876918091"
        ixz="-0.000211996995306677"
        iyy="0.050183888627592"
        iyz="0.000221416033215328"
        izz="0.0800251284551891" />
    </inertial>
    <visual>
      <origin
        xyz="0 0 0"
        rpy="0 0 0" />
      <geometry>
        <mesh
          filename="package://mega_robot_1st_urdf/meshes/trunk2.STL" />
      </geometry>
      <material
        name="">
        <color
          rgba="0.752941176470588 0.752941176470588 0.752941176470588 1" />
      </material>
    </visual>
    <collision>
      <origin
        xyz="0 0 0"
        rpy="0 0 0" />
      <geometry>
        <mesh
          filename="package://mega_robot_1st_urdf/meshes/trunk2.STL" />
      </geometry>
    </collision>
  </link>
  <joint
    name="trunk_J2"
    type="revolute">
    <origin
      xyz="0.119999999999998 0 0.415"
      rpy="-1.5707963267949 0 0" />
    <parent
      link="trunk1" />
    <child
      link="trunk2" />
    <axis
      xyz="0 0 -1" />
    <limit
      lower="-3.1416"
      upper="3.1416"
      effort="0"
      velocity="2.0" />
  </joint>
  <link
    name="trunk3">
    <inertial>
      <origin
        xyz="-0.0189532742276381 -0.281889600894594 -0.00158761458668278"
        rpy="0 0 0" />
      <mass
        value="11.5779315783688" />
      <inertia
        ixx="0.170888356917311"
        ixy="-0.00515900935423071"
        ixz="4.56480800395434E-06"
        iyy="0.10674854164018"
        iyz="-9.99130004001207E-05"
        izz="0.113508194749263" />
    </inertial>
    <visual>
      <origin
        xyz="0 0 0"
        rpy="0 0 0" />
      <geometry>
        <mesh
          filename="package://mega_robot_1st_urdf/meshes/trunk3.STL" />
      </geometry>
      <material
        name="">
        <color
          rgba="0.752941176470588 0.752941176470588 0.752941176470588 1" />
      </material>
    </visual>
    <collision>
      <origin
        xyz="0 0 0"
        rpy="0 0 0" />
      <geometry>
        <mesh
          filename="package://mega_robot_1st_urdf/meshes/trunk3.STL" />
      </geometry>
    </collision>
  </link>
  <joint
    name="trunk_J3"
    type="revolute">
    <origin
      xyz="-0.212132034355965 -0.212132034355963 0"
      rpy="0 0 0" />
    <parent
      link="trunk2" />
    <child
      link="trunk3" />
    <axis
      xyz="0 0 1" />
    <limit
      lower="-3.1416"
      upper="3.1416"
      effort="0"
      velocity="2.0" />
  </joint>
  <link
    name="Right_link1">
    <inertial>
      <origin
        xyz="-0.00505545041964467 1.72114415213365E-05 0.0770297301281596"
        rpy="0 0 0" />
      <mass
        value="1.84732823288651" />
      <inertia
        ixx="0.00279329043434002"
        ixy="-3.43377816561807E-07"
        ixz="4.04839387458964E-05"
        iyy="0.0026131092667569"
        iyz="4.02586914307371E-06"
        izz="0.00191849094781824" />
    </inertial>
    <visual>
      <origin
        xyz="0 0 0"
        rpy="0 0 0" />
      <geometry>
        <mesh
          filename="package://mega_robot_1st_urdf/meshes/Right_link1.STL" />
      </geometry>
      <material
        name="">
        <color
          rgba="0.752941176470588 0.752941176470588 0.752941176470588 1" />
      </material>
    </visual>
    <collision>
      <origin
        xyz="0 0 0"
        rpy="0 0 0" />
      <geometry>
        <mesh
          filename="package://mega_robot_1st_urdf/meshes/Right_link1.STL" />
      </geometry>
    </collision>
  </link>
  <joint
    name="Right_J1"
    type="revolute">
    <origin
      xyz="0 -0.384999999999999 0.136199999954927"
      rpy="0 0 0" />
    <parent
      link="trunk3" />
    <child
      link="Right_link1" />
    <axis
      xyz="0 0 1" />
    <limit
      lower="-2.8797"
      upper="2.8797"
      effort="0"
      velocity="2.0" />
  </joint>
  <link
    name="Right_link2">
    <inertial>
      <origin
        xyz="0.00139860673675998 -0.082958001314837 0.00308529881311936"
        rpy="0 0 0" />
      <mass
        value="1.6913399132769" />
      <inertia
        ixx="0.00334456509199785"
        ixy="-5.28514351037971E-05"
        ixz="5.48646999607133E-06"
        iyy="0.00242638789548501"
        iyz="-0.00053420499124214"
        izz="0.00287951206530337" />
    </inertial>
    <visual>
      <origin
        xyz="0 0 0"
        rpy="0 0 0" />
      <geometry>
        <mesh
          filename="package://mega_robot_1st_urdf/meshes/Right_link2.STL" />
      </geometry>
      <material
        name="">
        <color
          rgba="0.752941176470588 0.752941176470588 0.752941176470588 1" />
      </material>
    </visual>
    <collision>
      <origin
        xyz="0 0 0"
        rpy="0 0 0" />
      <geometry>
        <mesh
          filename="package://mega_robot_1st_urdf/meshes/Right_link2.STL" />
      </geometry>
    </collision>
  </link>
  <joint
    name="Right_J2"
    type="revolute">
    <origin
      xyz="0 0 0.0846"
      rpy="3.14159265358979 1.5707963267949 0" />
    <parent
      link="Right_link1" />
    <child
      link="Right_link2" />
    <axis
      xyz="0 0 1" />
    <limit
      lower="-1.9198"
      upper="0.08"
      effort="0"
      velocity="2.0" />
  </joint>
  <link
    name="Right_link3">
    <inertial>
      <origin
        xyz="0.000356309996875359 4.51149131632383E-05 -0.142967963660585"
        rpy="0 0 0" />
      <mass
        value="1.60131371593021" />
      <inertia
        ixx="0.00412433568031909"
        ixy="2.69896996356155E-10"
        ixz="-2.41331214211285E-05"
        iyy="0.00408254642115649"
        iyz="-1.49157507279543E-06"
        izz="0.0011921754423495" />
    </inertial>
    <visual>
      <origin
        xyz="0 0 0"
        rpy="0 0 0" />
      <geometry>
        <mesh
          filename="package://mega_robot_1st_urdf/meshes/Right_link3.STL" />
      </geometry>
      <material
        name="">
        <color
          rgba="0.752941176470588 0.752941176470588 0.752941176470588 1" />
      </material>
    </visual>
    <collision>
      <origin
        xyz="0 0 0"
        rpy="0 0 0" />
      <geometry>
        <mesh
          filename="package://mega_robot_1st_urdf/meshes/Right_link3.STL" />
      </geometry>
    </collision>
  </link>
  <joint
    name="Right_J3"
    type="revolute">
    <origin
      xyz="0 -0.141000000042135 0"
      rpy="-1.5707963267949 0 0" />
    <parent
      link="Right_link2" />
    <child
      link="Right_link3" />
    <axis
      xyz="0 0 -1" />
    <limit
      lower="-2.8797"
      upper="2.8797"
      effort="0"
      velocity="2.0" />
  </joint>
  <link
    name="Right_link4">
    <inertial>
      <origin
        xyz="-0.000181250438163486 0.0659431288815815 -0.0026888177360252"
        rpy="0 0 0" />
      <mass
        value="0.900300521226934" />
      <inertia
        ixx="0.00183183081996464"
        ixy="9.5762968380507E-07"
        ixz="3.15426124359246E-08"
        iyy="0.00112145322026532"
        iyz="-0.000229927361474667"
        izz="0.00139013604843393" />
    </inertial>
    <visual>
      <origin
        xyz="0 0 0"
        rpy="0 0 0" />
      <geometry>
        <mesh
          filename="package://mega_robot_1st_urdf/meshes/Right_link4.STL" />
      </geometry>
      <material
        name="">
        <color
          rgba="0.752941176470588 0.752941176470588 0.752941176470588 1" />
      </material>
    </visual>
    <collision>
      <origin
        xyz="0 0 0"
        rpy="0 0 0" />
      <geometry>
        <mesh
          filename="package://mega_robot_1st_urdf/meshes/Right_link4.STL" />
      </geometry>
    </collision>
  </link>
  <joint
    name="Right_J4"
    type="revolute">
    <origin
      xyz="0 0 -0.178999999999999"
      rpy="-1.5707963267949 0 -1.5707963267949" />
    <parent
      link="Right_link3" />
    <child
      link="Right_link4" />
    <axis
      xyz="0 0 -1" />
    <limit
      lower="-0.8753"
      upper="2.0943"
      effort="0"
      velocity="2.0" />
  </joint>
  <link
    name="Right_link5">
    <inertial>
      <origin
        xyz="0.00271219640113408 -0.0003783973927724 0.0714840699103813"
        rpy="0 0 0" />
      <mass
        value="0.979106958507518" />
      <inertia
        ixx="0.0017616424308103"
        ixy="-2.16407716693962E-06"
        ixz="6.00750189110706E-06"
        iyy="0.00146153510004494"
        iyz="1.15137727198048E-05"
        izz="0.000837998167905336" />
    </inertial>
    <visual>
      <origin
        xyz="0 0 0"
        rpy="0 0 0" />
      <geometry>
        <mesh
          filename="package://mega_robot_1st_urdf/meshes/Right_link5.STL" />
      </geometry>
      <material
        name="">
        <color
          rgba="0.752941176470588 0.752941176470588 0.752941176470588 1" />
      </material>
    </visual>
    <collision>
      <origin
        xyz="0 0 0"
        rpy="0 0 0" />
      <geometry>
        <mesh
          filename="package://mega_robot_1st_urdf/meshes/Right_link5.STL" />
      </geometry>
    </collision>
  </link>
  <joint
    name="Right_J5"
    type="revolute">
    <origin
      xyz="0 0.140000235405189 0"
      rpy="-1.5707963267949 0 0" />
    <parent
      link="Right_link4" />
    <child
      link="Right_link5" />
    <axis
      xyz="0 0 1" />
    <limit
      lower="-2.8797"
      upper="2.8797"
      effort="0"
      velocity="2.0" />
  </joint>
  <link
    name="Right_link6">
    <inertial>
      <origin
        xyz="-0.0028957902320417 -0.00043243929041048 -0.000356404128572657"
        rpy="0 0 0" />
      <mass
        value="0.420867737512087" />
      <inertia
        ixx="0.000337965296673012"
        ixy="8.66429998123206E-07"
        ixz="-6.73299542768556E-08"
        iyy="0.000390100767112464"
        iyz="9.14083087034326E-07"
        izz="0.000320727271120092" />
    </inertial>
    <visual>
      <origin
        xyz="0 0 0"
        rpy="0 0 0" />
      <geometry>
        <mesh
          filename="package://mega_robot_1st_urdf/meshes/Right_link6.STL" />
      </geometry>
      <material
        name="">
        <color
          rgba="0.752941176470588 0.752941176470588 0.752941176470588 1" />
      </material>
    </visual>
    <collision>
      <origin
        xyz="0 0 0"
        rpy="0 0 0" />
      <geometry>
        <mesh
          filename="package://mega_robot_1st_urdf/meshes/Right_link6.STL" />
      </geometry>
    </collision>
  </link>
  <joint
    name="Right_J6"
    type="revolute">
    <origin
      xyz="0 0 0.17"
      rpy="-1.5707963267949 0 1.5707963267949" />
    <parent
      link="Right_link5" />
    <child
      link="Right_link6" />
    <axis
      xyz="0 0 -1" />
    <limit
      lower="-0.6981"
      upper="0.6981"
      effort="0"
      velocity="2.0" />
  </joint>
  <link
    name="Right_link7">
    <inertial>
      <origin
        xyz="0.120129053548984 -0.0789155177388833 -0.00224025100512587"
        rpy="0 0 0" />
      <mass
        value="1.43249329589491" />
      <inertia
        ixx="0.00051212083876353"
        ixy="3.11213008789692E-05"
        ixz="-4.12169326210125E-05"
        iyy="0.000400286030920828"
        iyz="2.12861040627444E-07"
        izz="0.000418106140840993" />
    </inertial>
    <visual>
      <origin
        xyz="0 0 0"
        rpy="0 0 0" />
      <geometry>
        <mesh
          filename="package://mega_robot_1st_urdf/meshes/Right_link7.STL" />
      </geometry>
      <material
        name="">
        <color
          rgba="0.752941176470588 0.752941176470588 0.752941176470588 1" />
      </material>
    </visual>
    <collision>
      <origin
        xyz="0 0 0"
        rpy="0 0 0" />
      <geometry>
        <mesh
          filename="package://mega_robot_1st_urdf/meshes/Right_link7.STL" />
      </geometry>
    </collision>
  </link>
  <joint
    name="Right_J7"
    type="revolute">
    <origin
      xyz="0 0 0"
      rpy="1.5707963267949 0 -1.5707963267949" />
    <parent
      link="Right_link6" />
    <child
      link="Right_link7" />
    <axis
      xyz="0 0 -1" />
    <limit
      lower="-0.6981"
      upper="0.6981"
      effort="0"
      velocity="2.0" />
  </joint>
  <!--=============================================================================================-->
  <link
    name="rhand">
    <inertial>
      <origin
        xyz="-0.0534374129596824 -0.00157154809251104 0.0032467575274062"
        rpy="0 0 0" />
      <mass
        value="0.0941614898718946" />
      <inertia
        ixx="4.1962895621209E-05"
        ixy="-3.95936210501525E-07"
        ixz="3.71581889924585E-06"
        iyy="6.1906439028121E-05"
        iyz="-7.5091963461847E-07"
        izz="8.90989074913989E-05" />
    </inertial>
    <visual>
      <origin
        xyz="0 0 0"
        rpy="0 0 0" />
      <geometry>
        <box size="0.001 0.001 0.001" />
      </geometry>
      <material
        name="">
        <color
          rgba="1 1 1 1" />
      </material>
    </visual>
    <collision>
      <origin
        xyz="0 0 0"
        rpy="0 0 0" />
      <geometry>
        <box size="0.001 0.001 0.001" />
      </geometry>
    </collision>
  </link>
  <joint
    name="rfix_joint"
    type="fixed">
    <origin
      xyz="0.1041 0 0"
      rpy="0 0 0" />
    <parent
      link="Right_link7" />
    <child
      link="rhand" />
  </joint>
  <link
    name="right_tool">
    <visual>
      <origin
        xyz="0 0 0"
        rpy="0 0 0" />
      <geometry>
        <box size="0.001 0.001 0.001" />
      </geometry>
      <material
        name="">
        <color
          rgba="1 0 0 1" />
      </material>
    </visual>
    <collision>
      <origin
        xyz="0 0 0"
        rpy="0 0 0" />
      <geometry>
        <box size="0.001 0.001 0.001" />
      </geometry>
    </collision>
  </link>
  <joint
    name="right_tool_joint"
    type="fixed">
    <origin
      xyz="0 0 0"
      rpy="2.541592653589793 0 2.7707963267948967" />
    <parent
      link="rhand" />
    <child
      link="right_tool" />
  </joint>
  <!--=============================================================================================-->
  <link
    name="Left_link1">
    <inertial>
      <origin
        xyz="-0.00500386916983213 6.8114284875076E-05 0.0770416188389969"
        rpy="0 0 0" />
      <mass
        value="1.84968194199462" />
      <inertia
        ixx="0.00279330379014202"
        ixy="-5.84654216725077E-08"
        ixz="4.02616091975877E-05"
        iyy="0.00261775823177195"
        iyz="-6.68931767308275E-06"
        izz="0.00191388172921962" />
    </inertial>
    <visual>
      <origin
        xyz="0 0 0"
        rpy="0 0 0" />
      <geometry>
        <mesh
          filename="package://mega_robot_1st_urdf/meshes/Left_link1.STL" />
      </geometry>
      <material
        name="">
        <color
          rgba="0.752941176470588 0.752941176470588 0.752941176470588 1" />
      </material>
    </visual>
    <collision>
      <origin
        xyz="0 0 0"
        rpy="0 0 0" />
      <geometry>
        <mesh
          filename="package://mega_robot_1st_urdf/meshes/Left_link1.STL" />
      </geometry>
    </collision>
  </link>
  <joint
    name="Left_J1"
    type="revolute">
    <origin
      xyz="0 -0.384999999999999 -0.136199999954923"
      rpy="-3.14159265358979 0 0" />
    <parent
      link="trunk3" />
    <child
      link="Left_link1" />
    <axis
      xyz="0 0 1" />
    <limit
      lower="-2.8797"
      upper="2.8797"
      effort="0"
      velocity="2.0" />
  </joint>
  <link
    name="Left_link2">
    <inertial>
      <origin
        xyz="0.00138866225895184 0.0829258639861308 0.00305735020626537"
        rpy="0 0 0" />
      <mass
        value="1.69521073942591" />
      <inertia
        ixx="0.00334478442903094"
        ixy="5.28864539483985E-05"
        ixz="6.64103724299053E-06"
        iyy="0.00242676420369382"
        iyz="0.000532793134914777"
        izz="0.00287970536960663" />
    </inertial>
    <visual>
      <origin
        xyz="0 0 0"
        rpy="0 0 0" />
      <geometry>
        <mesh
          filename="package://mega_robot_1st_urdf/meshes/Left_link2.STL" />
      </geometry>
      <material
        name="">
        <color
          rgba="0.752941176470588 0.752941176470588 0.752941176470588 1" />
      </material>
    </visual>
    <collision>
      <origin
        xyz="0 0 0"
        rpy="0 0 0" />
      <geometry>
        <mesh
          filename="package://mega_robot_1st_urdf/meshes/Left_link2.STL" />
      </geometry>
    </collision>
  </link>
  <joint
    name="Left_J2"
    type="revolute">
    <origin
      xyz="0 0 0.0846000000000572"
      rpy="3.14159265358979 1.5707963267949 0" />
    <parent
      link="Left_link1" />
    <child
      link="Left_link2" />
    <axis
      xyz="0 0 1" />
    <limit
      lower="-0.08"
      upper="1.9198"
      effort="0"
      velocity="2.0" />
  </joint>
  <link
    name="Left_link3">
    <inertial>
      <origin
        xyz="-0.000367555850960877 0.000293466172618273 -0.142966836829543"
        rpy="0 0 0" />
      <mass
        value="1.60092526354409" />
      <inertia
        ixx="0.00412373487812428"
        ixy="1.75953094586558E-07"
        ixz="2.45154377441942E-05"
        iyy="0.00408186305304519"
        iyz="5.47695822000865E-06"
        izz="0.00119210849778722" />
    </inertial>
    <visual>
      <origin
        xyz="0 0 0"
        rpy="0 0 0" />
      <geometry>
        <mesh
          filename="package://mega_robot_1st_urdf/meshes/Left_link3.STL" />
      </geometry>
      <material
        name="">
        <color
          rgba="0.752941176470588 0.752941176470588 0.752941176470588 1" />
      </material>
    </visual>
    <collision>
      <origin
        xyz="0 0 0"
        rpy="0 0 0" />
      <geometry>
        <mesh
          filename="package://mega_robot_1st_urdf/meshes/Left_link3.STL" />
      </geometry>
    </collision>
  </link>
  <joint
    name="Left_J3"
    type="revolute">
    <origin
      xyz="0 0.141000000042135 0"
      rpy="-1.5707963267949 0 3.14159265358979" />
    <parent
      link="Left_link2" />
    <child
      link="Left_link3" />
    <axis
      xyz="0 0 -1" />
    <limit
      lower="-2.8797"
      upper="2.8797"
      effort="0"
      velocity="2.0" />
  </joint>
  <link
    name="Left_link4">
    <inertial>
      <origin
        xyz="-0.000175223109183803 -0.0658459532012505 -0.00270418667795383"
        rpy="0 0 0" />
      <mass
        value="0.905187997929622" />
      <inertia
        ixx="0.00183200973561433"
        ixy="-1.51501849173047E-06"
        ixz="3.09220787362469E-07"
        iyy="0.00112186442529009"
        iyz="0.000229873346417832"
        izz="0.0013902559001849" />
    </inertial>
    <visual>
      <origin
        xyz="0 0 0"
        rpy="0 0 0" />
      <geometry>
        <mesh
          filename="package://mega_robot_1st_urdf/meshes/Left_link4.STL" />
      </geometry>
      <material
        name="">
        <color
          rgba="0.752941176470588 0.752941176470588 0.752941176470588 1" />
      </material>
    </visual>
    <collision>
      <origin
        xyz="0 0 0"
        rpy="0 0 0" />
      <geometry>
        <mesh
          filename="package://mega_robot_1st_urdf/meshes/Left_link4.STL" />
      </geometry>
    </collision>
  </link>
  <joint
    name="Left_J4"
    type="revolute">
    <origin
      xyz="0 0 -0.178999999999999"
      rpy="1.5707963267949 0 -1.5707963267949" />
    <parent
      link="Left_link3" />
    <child
      link="Left_link4" />
    <axis
      xyz="0 0 -1" />
    <limit
      lower="-2.0943"
      upper="0.8753"
      effort="0"
      velocity="2.0" />
  </joint>
  <link
    name="Left_link5">
    <inertial>
      <origin
        xyz="0.00266530476424733 0.000327828508142392 0.0708463056028884"
        rpy="0 0 0" />
      <mass
        value="0.982128625414584" />
      <inertia
        ixx="0.00176189048711928"
        ixy="1.5870088985578E-06"
        ixz="6.00738367812395E-06"
        iyy="0.00146158754665338"
        iyz="-1.14554519785564E-05"
        izz="0.000838164001964768" />
    </inertial>
    <visual>
      <origin
        xyz="0 0 0"
        rpy="0 0 0" />
      <geometry>
        <mesh
          filename="package://mega_robot_1st_urdf/meshes/Left_link5.STL" />
      </geometry>
      <material
        name="">
        <color
          rgba="0.752941176470588 0.752941176470588 0.752941176470588 1" />
      </material>
    </visual>
    <collision>
      <origin
        xyz="0 0 0"
        rpy="0 0 0" />
      <geometry>
        <mesh
          filename="package://mega_robot_1st_urdf/meshes/Left_link5.STL" />
      </geometry>
    </collision>
  </link>
  <joint
    name="Left_J5"
    type="revolute">
    <origin
      xyz="0 -0.140000235405188 0"
      rpy="1.5707963267949 0 0" />
    <parent
      link="Left_link4" />
    <child
      link="Left_link5" />
    <axis
      xyz="0 0 1" />
    <limit
      lower="-2.8797"
      upper="2.8797"
      effort="0"
      velocity="2.0" />
  </joint>
  <link
    name="Left_link6">
    <inertial>
      <origin
        xyz="0.00313972914203789 -0.000424137182756912 -0.000346915113882615"
        rpy="0 0 0" />
      <mass
        value="0.426937710690489" />
      <inertia
        ixx="0.000337970988333306"
        ixy="-8.87070844279326E-07"
        ixz="1.36924697153749E-08"
        iyy="0.000389890567456002"
        iyz="6.66276072042788E-07"
        izz="0.000321057468945456" />
    </inertial>
    <visual>
      <origin
        xyz="0 0 0"
        rpy="0 0 0" />
      <geometry>
        <mesh
          filename="package://mega_robot_1st_urdf/meshes/Left_link6.STL" />
      </geometry>
      <material
        name="">
        <color
          rgba="0.752941176470588 0.752941176470588 0.752941176470588 1" />
      </material>
    </visual>
    <collision>
      <origin
        xyz="0 0 0"
        rpy="0 0 0" />
      <geometry>
        <mesh
          filename="package://mega_robot_1st_urdf/meshes/Left_link6.STL" />
      </geometry>
    </collision>
  </link>
  <joint
    name="Left_J6"
    type="revolute">
    <origin
      xyz="0 0 0.17"
      rpy="-1.5707963267949 0 1.5707963267949" />
    <parent
      link="Left_link5" />
    <child
      link="Left_link6" />
    <axis
      xyz="0 0 -1" />
    <limit
      lower="-0.6981"
      upper="0.6981"
      effort="0"
      velocity="2.0" />
  </joint>
  <link
    name="Left_link7">
    <inertial>
      <origin
        xyz="0.0789085515759982 -0.120129053794828 -0.00235180459600165"
        rpy="0 0 0" />
      <mass
        value="1.43249328899626" />
      <inertia
        ixx="0.000400286029330759"
        ixy="3.0973412578506E-05"
        ixz="2.12860849374747E-07"
        iyy="0.000512120837302201"
        iyz="4.1725446162325E-05"
        izz="0.00041810614059555" />
    </inertial>
    <visual>
      <origin
        xyz="0 0 0"
        rpy="0 0 0" />
      <geometry>
        <mesh
          filename="package://mega_robot_1st_urdf/meshes/Left_link7.STL" />
      </geometry>
      <material
        name="">
        <color
          rgba="0.752941176470588 0.752941176470588 0.752941176470588 1" />
      </material>
    </visual>
    <collision>
      <origin
        xyz="0 0 0"
        rpy="0 0 0" />
      <geometry>
        <mesh
          filename="package://mega_robot_1st_urdf/meshes/Left_link7.STL" />
      </geometry>
    </collision>
  </link>
  <joint
    name="Left_J7"
    type="revolute">
    <origin
      xyz="0 0 0"
      rpy="0 1.5707963267949 0" />
    <parent
      link="Left_link6" />
    <child
      link="Left_link7" />
    <axis
      xyz="0 0 -1" />
    <limit
      lower="-0.6981"
      upper="0.6981"
      effort="0"
      velocity="2.0" />
  </joint>
  
  
  <link
    name="lhand">
    <inertial>
      <origin
        xyz="-0.0534374129596824 -0.00157154809251104 0.0032467575274062"
        rpy="0 0 0" />
      <mass
        value="0.0941614898718946" />
      <inertia
        ixx="4.1962895621209E-05"
        ixy="-3.95936210501525E-07"
        ixz="3.71581889924585E-06"
        iyy="6.1906439028121E-05"
        iyz="-7.5091963461847E-07"
        izz="8.90989074913989E-05" />
    </inertial>
    <visual>
      <origin
        xyz="0 0 0"
        rpy="0 0 0" />
      <geometry>
        <box size="0.001 0.001 0.001" />
      </geometry>
      <material
        name="">
        <color
          rgba="1 1 1 1" />
      </material>
    </visual>
    <collision>
      <origin
        xyz="0 0 0"
        rpy="0 0 0" />
      <geometry>
        <box size="0.001 0.001 0.001" />
      </geometry>
    </collision>
  </link>
  <joint
    name="lfix_joint"
    type="fixed">
    <origin
      xyz="0 -0.1041 0"
      rpy="3.1416 0 -1.5708" />
    <parent
      link="Left_link7" />
    <child
      link="lhand" />
  </joint>
  <link
    name="left_tool">
    <visual>
      <origin
        xyz="0 0 0"
        rpy="0 0 0" />
      <geometry>
        <box size="0.001 0.001 0.001" />
      </geometry>
      <material
        name="">
        <color
          rgba="0 0 1 1" />
      </material>
    </visual>
    <collision>
      <origin
        xyz="0 0 0"
        rpy="0 0 0" />
      <geometry>
        <box size="0.001 0.001 0.001" />
      </geometry>
    </collision>
  </link>
  <joint
    name="left_tool_joint"
    type="fixed">
    <origin
      xyz="0 0 0"
      rpy="-2.541592653589793 0 2.7707963267948967" />
    <parent
      link="lhand" />
    <child
      link="left_tool" />
  </joint>
  
  <link
    name="Head1">
    <inertial>
      <origin
        xyz="0.000983552400225435 0.00138677279302025 0.0981541958756826"
        rpy="0 0 0" />
      <mass
        value="0.436405161381563" />
      <inertia
        ixx="0.000628142535942276"
        ixy="2.74158090116765E-07"
        ixz="-6.13209678978339E-05"
        iyy="0.000675664905952517"
        iyz="3.87633250033281E-05"
        izz="0.000485401374527524" />
    </inertial>
    <visual>
      <origin
        xyz="0 0 0"
        rpy="0 0 0" />
      <geometry>
        <mesh
          filename="package://mega_robot_1st_urdf/meshes/Head1.STL" />
      </geometry>
      <material
        name="">
        <color
          rgba="0.752941176470588 0.752941176470588 0.752941176470588 1" />
      </material>
    </visual>
    <collision>
      <origin
        xyz="0 0 0"
        rpy="0 0 0" />
      <geometry>
        <mesh
          filename="package://mega_robot_1st_urdf/meshes/Head1.STL" />
      </geometry>
    </collision>
  </link>
  <joint
    name="Head_J1"
    type="revolute">
    <origin
      xyz="0 -0.467500000000006 0"
      rpy="1.5707963267949 0 0" />
    <parent
      link="trunk3" />
    <child
      link="Head1" />
    <axis
      xyz="0 0 1" />
    <limit
      lower="-3.1416"
      upper="3.1416"
      effort="0"
      velocity="2.0" />
  </joint>
  <link
    name="Head2">
    <inertial>
      <origin
        xyz="-0.0205813385227401 0.0488189896506739 0.00277394760061114"
        rpy="0 0 0" />
      <mass
        value="0.710704129574505" />
      <inertia
        ixx="0.00157984868170601"
        ixy="-0.000421246275027292"
        ixz="-5.76084773684949E-09"
        iyy="0.00165175128691173"
        iyz="-1.08420051411845E-06"
        izz="0.00177517156573017" />
    </inertial>
    <visual>
      <origin
        xyz="0 0 0"
        rpy="0 0 0" />
      <geometry>
        <mesh
          filename="package://mega_robot_1st_urdf/meshes/Head2.STL" />
      </geometry>
      <material
        name="">
        <color
          rgba="0.752941176470588 0.752941176470588 0.752941176470588 1" />
      </material>
    </visual>
    <collision>
      <origin
        xyz="0 0 0"
        rpy="0 0 0" />
      <geometry>
        <mesh
          filename="package://mega_robot_1st_urdf/meshes/Head2.STL" />
      </geometry>
    </collision>
  </link>
  <joint
    name="Head_J2"
    type="revolute">
    <origin
      xyz="0 0 0.128500000000001"
      rpy="1.5707963267949 0 0" />
    <parent
      link="Head1" />
    <child
      link="Head2" />
    <axis
      xyz="0 0 1" />
    <limit
      lower="-3.1416"
      upper="3.1416"
      effort="0"
      velocity="2.0" />
  </joint>
</robot>
